Internal Server Error: /api/profile/
Traceback (most recent call last):
  File "/home/ubuntu/.local/lib/python3.10/site-packages/django/db/backends/mysql/base.py", line 76, in execute
    return self.cursor.execute(query, args)
  File "/home/ubuntu/.local/lib/python3.10/site-packages/MySQLdb/cursors.py", line 206, in execute
    res = self._query(query)
  File "/home/ubuntu/.local/lib/python3.10/site-packages/MySQLdb/cursors.py", line 319, in _query
    db.query(q)
  File "/home/ubuntu/.local/lib/python3.10/site-packages/MySQLdb/connections.py", line 254, in query
    _mysql.connection.query(self, query)
MySQLdb.OperationalError: (1048, "Column 'email_id' cannot be null")

During handling of the above exception, another exception occurred:

Traceback (most recent call last):
  File "/home/ubuntu/.local/lib/python3.10/site-packages/django/core/handlers/exception.py", line 55, in inner
    response = get_response(request)
  File "/home/ubuntu/.local/lib/python3.10/site-packages/django/core/handlers/base.py", line 197, in _get_response
    response = wrapped_callback(request, *callback_args, **callback_kwargs)
  File "/home/ubuntu/.local/lib/python3.10/site-packages/django/views/decorators/csrf.py", line 65, in _view_wrapper
    return view_func(request, *args, **kwargs)
  File "/home/ubuntu/.local/lib/python3.10/site-packages/django/views/generic/base.py", line 104, in view
    return self.dispatch(request, *args, **kwargs)
  File "/home/ubuntu/.local/lib/python3.10/site-packages/rest_framework/views.py", line 509, in dispatch
    response = self.handle_exception(exc)
  File "/home/ubuntu/.local/lib/python3.10/site-packages/rest_framework/views.py", line 469, in handle_exception
    self.raise_uncaught_exception(exc)
  File "/home/ubuntu/.local/lib/python3.10/site-packages/rest_framework/views.py", line 480, in raise_uncaught_exception
    raise exc
  File "/home/ubuntu/.local/lib/python3.10/site-packages/rest_framework/views.py", line 506, in dispatch
    response = handler(request, *args, **kwargs)
  File "/home/ubuntu/Week2_back_real/blog/views.py", line 108, in post
    profile = serializer.save()
  File "/home/ubuntu/.local/lib/python3.10/site-packages/rest_framework/serializers.py", line 208, in save
    self.instance = self.create(validated_data)
  File "/home/ubuntu/Week2_back_real/blog/serializers.py", line 92, in create
    profile = Profile.objects.create(**validated_data)
  File "/home/ubuntu/.local/lib/python3.10/site-packages/django/db/models/manager.py", line 87, in manager_method
    return getattr(self.get_queryset(), name)(*args, **kwargs)
  File "/home/ubuntu/.local/lib/python3.10/site-packages/django/db/models/query.py", line 679, in create
    obj.save(force_insert=True, using=self.db)
  File "/home/ubuntu/.local/lib/python3.10/site-packages/django/db/models/base.py", line 822, in save
    self.save_base(
  File "/home/ubuntu/.local/lib/python3.10/site-packages/django/db/models/base.py", line 909, in save_base
    updated = self._save_table(
  File "/home/ubuntu/.local/lib/python3.10/site-packages/django/db/models/base.py", line 1071, in _save_table
    results = self._do_insert(
  File "/home/ubuntu/.local/lib/python3.10/site-packages/django/db/models/base.py", line 1112, in _do_insert
    return manager._insert(
  File "/home/ubuntu/.local/lib/python3.10/site-packages/django/db/models/manager.py", line 87, in manager_method
    return getattr(self.get_queryset(), name)(*args, **kwargs)
  File "/home/ubuntu/.local/lib/python3.10/site-packages/django/db/models/query.py", line 1847, in _insert
    return query.get_compiler(using=using).execute_sql(returning_fields)
  File "/home/ubuntu/.local/lib/python3.10/site-packages/django/db/models/sql/compiler.py", line 1823, in execute_sql
    cursor.execute(sql, params)
  File "/home/ubuntu/.local/lib/python3.10/site-packages/django/db/backends/utils.py", line 122, in execute
    return super().execute(sql, params)
  File "/home/ubuntu/.local/lib/python3.10/site-packages/django/db/backends/utils.py", line 79, in execute
    return self._execute_with_wrappers(
  File "/home/ubuntu/.local/lib/python3.10/site-packages/django/db/backends/utils.py", line 92, in _execute_with_wrappers
    return executor(sql, params, many, context)
  File "/home/ubuntu/.local/lib/python3.10/site-packages/django/db/backends/utils.py", line 105, in _execute
    return self.cursor.execute(sql, params)
  File "/home/ubuntu/.local/lib/python3.10/site-packages/django/db/backends/mysql/base.py", line 81, in execute
    raise IntegrityError(*tuple(e.args))
django.db.utils.IntegrityError: (1048, "Column 'email_id' cannot be null")
"POST /api/profile/ HTTP/1.1" 500 189732
Internal Server Error: /api/profile/
Traceback (most recent call last):
  File "/home/ubuntu/.local/lib/python3.10/site-packages/django/core/handlers/exception.py", line 55, in inner
    response = get_response(request)
  File "/home/ubuntu/.local/lib/python3.10/site-packages/django/core/handlers/base.py", line 197, in _get_response
    response = wrapped_callback(request, *callback_args, **callback_kwargs)
  File "/home/ubuntu/.local/lib/python3.10/site-packages/django/views/decorators/csrf.py", line 65, in _view_wrapper
    return view_func(request, *args, **kwargs)
  File "/home/ubuntu/.local/lib/python3.10/site-packages/django/views/generic/base.py", line 104, in view
    return self.dispatch(request, *args, **kwargs)
  File "/home/ubuntu/.local/lib/python3.10/site-packages/rest_framework/views.py", line 509, in dispatch
    response = self.handle_exception(exc)
  File "/home/ubuntu/.local/lib/python3.10/site-packages/rest_framework/views.py", line 469, in handle_exception
    self.raise_uncaught_exception(exc)
  File "/home/ubuntu/.local/lib/python3.10/site-packages/rest_framework/views.py", line 480, in raise_uncaught_exception
    raise exc
  File "/home/ubuntu/.local/lib/python3.10/site-packages/rest_framework/views.py", line 506, in dispatch
    response = handler(request, *args, **kwargs)
  File "/home/ubuntu/Week2_back_real/blog/views.py", line 118, in post
    profile = serializer.save()
  File "/home/ubuntu/.local/lib/python3.10/site-packages/rest_framework/serializers.py", line 208, in save
    self.instance = self.create(validated_data)
  File "/home/ubuntu/Week2_back_real/blog/serializers.py", line 112, in create
    profile = Profile.objects.create(email=user, **validated_data)
  File "/home/ubuntu/.local/lib/python3.10/site-packages/django/db/models/manager.py", line 87, in manager_method
    return getattr(self.get_queryset(), name)(*args, **kwargs)
  File "/home/ubuntu/.local/lib/python3.10/site-packages/django/db/models/query.py", line 677, in create
    obj = self.model(**kwargs)
  File "/home/ubuntu/.local/lib/python3.10/site-packages/django/db/models/base.py", line 567, in __init__
    raise TypeError(
TypeError: Profile() got unexpected keyword arguments: 'tech_tags'
"POST /api/profile/ HTTP/1.1" 500 120017
